{
 "cells": [
  {
   "cell_type": "markdown",
   "metadata": {},
   "source": [
    "# Multiple Exception Handling\n",
    "\n",
    "There are many different types of exceptions that can be raised in Python. For example, the following is an example of a `ValueError` exception:"
   ]
  },
  {
   "cell_type": "code",
   "execution_count": 1,
   "metadata": {},
   "outputs": [
    {
     "ename": "ValueError",
     "evalue": "invalid literal for int() with base 10: 'a'",
     "output_type": "error",
     "traceback": [
      "\u001b[0;31m---------------------------------------------------------------------------\u001b[0m",
      "\u001b[0;31mValueError\u001b[0m                                Traceback (most recent call last)",
      "Cell \u001b[0;32mIn[1], line 1\u001b[0m\n\u001b[0;32m----> 1\u001b[0m \u001b[38;5;28;43mint\u001b[39;49m\u001b[43m(\u001b[49m\u001b[38;5;124;43m'\u001b[39;49m\u001b[38;5;124;43ma\u001b[39;49m\u001b[38;5;124;43m'\u001b[39;49m\u001b[43m)\u001b[49m\n",
      "\u001b[0;31mValueError\u001b[0m: invalid literal for int() with base 10: 'a'"
     ]
    }
   ],
   "source": [
    "int('a')"
   ]
  },
  {
   "cell_type": "markdown",
   "metadata": {},
   "source": [
    "The following is an example of an `IndexError` that occurs when trying to access an element at an index that is out of range:"
   ]
  },
  {
   "cell_type": "code",
   "execution_count": 2,
   "metadata": {},
   "outputs": [
    {
     "ename": "IndexError",
     "evalue": "list index out of range",
     "output_type": "error",
     "traceback": [
      "\u001b[0;31m---------------------------------------------------------------------------\u001b[0m",
      "\u001b[0;31mIndexError\u001b[0m                                Traceback (most recent call last)",
      "Cell \u001b[0;32mIn[2], line 3\u001b[0m\n\u001b[1;32m      1\u001b[0m list1 \u001b[38;5;241m=\u001b[39m [\u001b[38;5;241m1\u001b[39m, \u001b[38;5;241m2\u001b[39m, \u001b[38;5;241m3\u001b[39m]\n\u001b[0;32m----> 3\u001b[0m \u001b[43mlist1\u001b[49m\u001b[43m[\u001b[49m\u001b[38;5;241;43m5\u001b[39;49m\u001b[43m]\u001b[49m\n",
      "\u001b[0;31mIndexError\u001b[0m: list index out of range"
     ]
    }
   ],
   "source": [
    "list1 = [1, 2, 3]\n",
    "\n",
    "list1[5]"
   ]
  },
  {
   "cell_type": "markdown",
   "metadata": {},
   "source": [
    "The following is a `ZeroDivisionError` exception:"
   ]
  },
  {
   "cell_type": "code",
   "execution_count": 3,
   "metadata": {},
   "outputs": [
    {
     "ename": "ZeroDivisionError",
     "evalue": "division by zero",
     "output_type": "error",
     "traceback": [
      "\u001b[0;31m---------------------------------------------------------------------------\u001b[0m",
      "\u001b[0;31mZeroDivisionError\u001b[0m                         Traceback (most recent call last)",
      "Cell \u001b[0;32mIn[3], line 1\u001b[0m\n\u001b[0;32m----> 1\u001b[0m \u001b[38;5;241;43m5\u001b[39;49m\u001b[38;5;241;43m/\u001b[39;49m\u001b[38;5;241;43m0\u001b[39;49m\n",
      "\u001b[0;31mZeroDivisionError\u001b[0m: division by zero"
     ]
    }
   ],
   "source": [
    "5/0"
   ]
  },
  {
   "cell_type": "markdown",
   "metadata": {},
   "source": [
    "It is often the case that we want to handle different exceptions in different ways. For example, we may want to print a different message for a `ValueError` than for a `ZeroDivisionError`. We can do this by using multiple `except` blocks."
   ]
  },
  {
   "cell_type": "code",
   "execution_count": 5,
   "metadata": {},
   "outputs": [
    {
     "name": "stdout",
     "output_type": "stream",
     "text": [
      "Cannot divide by zero.\n"
     ]
    }
   ],
   "source": [
    "try:\n",
    "    num1 = int(input(\"Enter a number: \"))\n",
    "    num2 = int(input(\"Enter another number: \"))\n",
    "    result = num1 / num2\n",
    "    print(result)\n",
    "except ValueError:\n",
    "    print(\"Please enter a valid number.\")\n",
    "except ZeroDivisionError:\n",
    "    print(\"Cannot divide by zero.\")"
   ]
  },
  {
   "cell_type": "markdown",
   "metadata": {},
   "source": [
    "In the above code, we have two `except` blocks. The first one handles the `ValueError` exception, and the second one handles the `ZeroDivisionError` exception. This way, the error message that is printed is more specific to the error that occurred.\n",
    "\n",
    "What if we executed the above code and no `ValueError` or `ZeroDivisionError` exception was raised, but instead a `IndexError` exception was raised? In this case, the code would not be able to handle the `IndexError` exception, and the program would crash. To handle this, we can use a final  `except` block that handles any other type of exception that is not handled by the previous `except` blocks:"
   ]
  },
  {
   "cell_type": "code",
   "execution_count": null,
   "metadata": {},
   "outputs": [],
   "source": [
    "try:\n",
    "    num1 = int(input(\"Enter a number: \"))\n",
    "    num2 = int(input(\"Enter another number: \"))\n",
    "    result = num1 / num2\n",
    "    print(result)\n",
    "except (ValueError, TypeError):\n",
    "    print(\"Please enter a valid number.\")\n",
    "except ZeroDivisionError:\n",
    "    print(\"Cannot divide by zero.\")\n",
    "except:\n",
    "    print(\"An error occurred.\")"
   ]
  },
  {
   "cell_type": "markdown",
   "metadata": {},
   "source": [
    "In the code above, I have also added the `TypeError` to the except block that handles the `ValueError` for illustration purposes. This shows how to handle more than one type of error in a single except block. Note that multiple error types are handled by using a tuple."
   ]
  }
 ],
 "metadata": {
  "kernelspec": {
   "display_name": "McGill",
   "language": "python",
   "name": "python3"
  },
  "language_info": {
   "codemirror_mode": {
    "name": "ipython",
    "version": 3
   },
   "file_extension": ".py",
   "mimetype": "text/x-python",
   "name": "python",
   "nbconvert_exporter": "python",
   "pygments_lexer": "ipython3",
   "version": "3.12.4"
  }
 },
 "nbformat": 4,
 "nbformat_minor": 2
}
